Workbook

Sheet 一覧
A1: No | B1: コード | C1: 会社名 | D1: 市場 | E1: 東証33業種 | F1: 区分 | G1: 主分類 | H1: 副分類 | I1: 主な事業 | J1: 分類の確度 | K1: 根拠（2026年10月に調査した34社）
A2: 1 | B2: 3231 | C2: 野村不動産ホールディングス | D2: プライム | E2: 不動産業 | F2: 不動産業 | G2: 総合デベ | H2: マンション | I2: 総合不動産（プラウド） | J2: 高
A3: 2 | B3: 3289 | C3: 東急不動産ホールディングス | D3: プライム | E3: 不動産業 | F3: 不動産業 | G3: 総合デベ | H3: マンション | I3: 総合不動産（ブランズ） | J3: 高
A4: 3 | B4: 8801 | C4: 三井不動産 | D4: プライム | E4: 不動産業 | F4: 不動産業 | G4: 総合デベ | H4: ビル・商業 | I4: 総合不動産（三井のリハウス） | J4: 高
A5: 4 | B5: 8802 | C5: 三菱地所 | D5: プライム | E5: 不動産業 | F5: 不動産業 | G5: 総合デベ | H5: ビル・商業 | I5: 総合不動産（丸の内） | J5: 高
A6: 5 | B6: 8804 | C6: 東京建物 | D6: プライム | E6: 不動産業 | F6: 不動産業 | G6: 総合デベ | H6: マンション | I6: 総合不動産（ブリリア） | J6: 高
A7: 6 | B7: 8830 | C7: 住友不動産 | D7: プライム | E7: 不動産業 | F7: 不動産業 | G7: 総合デベ | H7: マンション | I7: 総合不動産（住友不動産販売→ステップ） | J7: 高
A8: 7 | B8: 3284 | C8: フージャースホールディングス | D8: プライム | E8: 不動産業 | F8: 不動産業 | G8: マンション | I8: マンション分譲（シニア向け含む） | J8: 高
A9: 8 | B9: 8881 | C9: 日神グループホールディングス | D9: プライム | E9: 不動産業 | F9: 不動産業 | G9: マンション | I9: マンション分譲 | J9: 高
A10: 9 | B10: 8892 | C10: エスコン | D10: プライム | E10: 不動産業 | F10: 不動産業 | G10: マンション | H10: ビル・商業 | I10: マンション分譲・商業施設開発 | J10: 高
A11: 10 | B11: 8897 | C11: MIRARTHホールディングス | D11: プライム | E11: 不動産業 | F11: 不動産業 | G11: マンション | I11: マンション分譲（旧タカラレーベン） | J11: 高
A12: 11 | B12: 3236 | C12: プロパスト | D12: スタンダード | E12: 不動産業 | F12: 不動産業 | G12: マンション | H12: 投資用 | I12: マンション開発・収益不動産 | J12: 中
A13: 12 | B13: 3238 | C13: セントラル総合開発 | D13: スタンダード | E13: 不動産業 | F13: 不動産業 | G13: マンション | I13: マンション分譲 | J13: 中
A14: 13 | B14: 3246 | C14: コーセーアールイー | D14: スタンダード | E14: 不動産業 | F14: 不動産業 | G14: マンション | H14: 投資用 | I14: マンション分譲・投資用（福岡） | J14: 中
A15: 14 | B15: 3280 | C15: エストラスト | D15: スタンダード | E15: 不動産業 | F15: 不動産業 | G15: マンション | H15: 戸建て | I15: マンション・戸建て分譲（山口） | J15: 中
A16: 15 | B16: 5280 | C16: ヨシコン | D16: スタンダード | E16: 不動産業 | F16: 不動産業 | G16: マンション | I16: マンション分譲・収益不動産（静岡） | J16: 中
A17: 16 | B17: 8844 | C17: コスモスイニシア | D17: スタンダード | E17: 不動産業 | F17: 不動産業 | G17: マンション | H17: 投資用 | I17: マンション分譲・投資用 | J17: 高
A18: 17 | B18: 8869 | C18: 明和地所 | D18: スタンダード | E18: 不動産業 | F18: 不動産業 | G18: マンション | I18: マンション分譲 | J18: 中
A19: 18 | B19: 8871 | C19: ゴールドクレスト | D19: スタンダード | E19: 不動産業 | F19: 不動産業 | G19: マンション | I19: マンション分譲 | J19: 中
A20: 19 | B20: 8918 | C20: ランド | D20: スタンダード | E20: 不動産業 | F20: 不動産業 | G20: マンション | H20: ファンド・再生 | I20: マンション・不動産再生 | J20: 中
A21: 20 | B21: 8928 | C21: 穴吹興産 | D21: スタンダード | E21: 不動産業 | F21: 不動産業 | G21: マンション | I21: マンション分譲（香川） | J21: 高
A22: 21 | B22: 8931 | C22: 和田興産 | D22: スタンダード | E22: 不動産業 | F22: 不動産業 | G22: マンション | I22: マンション分譲（神戸） | J22: 中
A23: 22 | B23: 2986 | C23: LAホールディングス | D23: グロース | E23: 不動産業 | F23: 不動産業 | G23: マンション | H23: 投資用 | I23: 新築マンション・収益不動産の開発・再生 | J23: 中
A24: 23 | B24: 2995 | C24: ジェイレックス・コーポレーション | D24: PRO Market | E24: 不動産業 | F24: 不動産業 | G24: マンション | H24: 投資用 | I24: 自社ブランドマンション開発販売（東京） | J24: 中 | K24: https://jp.investing.com/equities/j-rex-corp
A25: 24 | B25: 3288 | C25: オープンハウスグループ | D25: プライム | E25: 不動産業 | F25: 不動産業 | G25: 戸建て | H25: マンション | I25: 都市型戸建て・マンション・投資用 | J25: 高
A26: 25 | B26: 3291 | C26: 飯田グループホールディングス | D26: プライム | E26: 不動産業 | F26: 不動産業 | G26: 戸建て | I26: 戸建て分譲（国内最大手） | J26: 高
A27: 26 | B27: 3465 | C27: ケイアイスター不動産 | D27: プライム | E27: 不動産業 | F27: 不動産業 | G27: 戸建て | I27: 戸建て分譲 | J27: 高
A28: 27 | B28: 8860 | C28: フジ住宅 | D28: プライム | E28: 不動産業 | F28: 不動産業 | G28: 戸建て | H28: マンション | I28: 戸建て・マンション分譲・賃貸管理（大阪） | J28: 高
A29: 28 | B29: 8999 | C29: グランディハウス | D29: プライム | E29: 不動産業 | F29: 不動産業 | G29: 戸建て | I29: 戸建て分譲（栃木） | J29: 高
A30: 29 | B30: 2984 | C30: ヤマイチエステート | D30: スタンダード | E30: 不動産業 | F30: 不動産業 | G30: 戸建て | H30: 注文住宅 | I30: 戸建て分譲・注文住宅（和歌山） | J30: 中
A31: 30 | B31: 2999 | C31: ホームポジション | D31: スタンダード | E31: 不動産業 | F31: 不動産業 | G31: 戸建て | I31: 戸建て分譲（東海） | J31: 中
A32: 31 | B32: 3293 | C32: アズマハウス | D32: スタンダード | E32: 不動産業 | F32: 不動産業 | G32: 戸建て | H32: アパート・賃貸住宅 | I32: 戸建て分譲・賃貸（和歌山） | J32: 中
A33: 32 | B33: 3467 | C33: アグレ都市デザイン | D33: スタンダード | E33: 不動産業 | F33: 不動産業 | G33: 戸建て | I33: 戸建て分譲 | J33: 中
A34: 33 | B34: 8904 | C34: AVANTIA | D34: スタンダード | E34: 不動産業 | F34: 不動産業 | G34: 戸建て | I34: 戸建て分譲（東海） | J34: 高
A35: 34 | B35: 8917 | C35: ファースト住建 | D35: スタンダード | E35: 不動産業 | F35: 不動産業 | G35: 戸建て | I35: 戸建て分譲（関西） | J35: 中
A36: 35 | B36: 8995 | C36: 誠建設工業 | D36: スタンダード | E36: 不動産業 | F36: 不動産業 | G36: 戸建て | I36: 戸建て分譲（大阪） | J36: 中
A37: 36 | B37: 8996 | C37: ハウスフリーダム | D37: スタンダード | E37: 不動産業 | F37: 不動産業 | G37: 戸建て | H37: 仲介 | I37: 戸建て分譲・仲介（福岡） | J37: 中
A38: 37 | B38: 2983 | C38: アールプランナー | D38: グロース | E38: 不動産業 | F38: 不動産業 | G38: 戸建て | H38: 注文住宅 | I38: 戸建て分譲・注文住宅（東京・名古屋） | J38: 中
A39: 38 | B39: 3261 | C39: グランディーズ | D39: グロース | E39: 不動産業 | F39: 不動産業 | G39: 戸建て | I39: 戸建て分譲（大分） | J39: 中
A40: 39 | B40: 3477 | C40: フォーライフ | D40: グロース | E40: 不動産業 | F40: 不動産業 | G40: 戸建て | I40: 戸建て分譲 | J40: 中
...

Sheet 分類別の社数
A1: 分類 | B1: 主分類の社数 | C1: 副分類も含む社数 | D1: うちプライム（主分類）
A2: 総合デベ | B2: =COUNTIF(一覧!$G$2:$G$178,A2) | C2: =COUNTIF(一覧!$G$2:$G$178,A2)+COUNTIF(一覧!$H$2:$H$178,A2) | D2: =COUNTIFS(一覧!$G$2:$G$178,A2,一覧!$D$2:$D$178,"プライム")
A3: マンション | B3: =COUNTIF(一覧!$G$2:$G$178,A3) | C3: =COUNTIF(一覧!$G$2:$G$178,A3)+COUNTIF(一覧!$H$2:$H$178,A3) | D3: =COUNTIFS(一覧!$G$2:$G$178,A3,一覧!$D$2:$D$178,"プライム")
A4: 戸建て | B4: =COUNTIF(一覧!$G$2:$G$178,A4) | C4: =COUNTIF(一覧!$G$2:$G$178,A4)+COUNTIF(一覧!$H$2:$H$178,A4) | D4: =COUNTIFS(一覧!$G$2:$G$178,A4,一覧!$D$2:$D$178,"プライム")
A5: 注文住宅 | B5: =COUNTIF(一覧!$G$2:$G$178,A5) | C5: =COUNTIF(一覧!$G$2:$G$178,A5)+COUNTIF(一覧!$H$2:$H$178,A5) | D5: =COUNTIFS(一覧!$G$2:$G$178,A5,一覧!$D$2:$D$178,"プライム")
A6: アパート・賃貸住宅 | B6: =COUNTIF(一覧!$G$2:$G$178,A6) | C6: =COUNTIF(一覧!$G$2:$G$178,A6)+COUNTIF(一覧!$H$2:$H$178,A6) | D6: =COUNTIFS(一覧!$G$2:$G$178,A6,一覧!$D$2:$D$178,"プライム")
A7: 投資用 | B7: =COUNTIF(一覧!$G$2:$G$178,A7) | C7: =COUNTIF(一覧!$G$2:$G$178,A7)+COUNTIF(一覧!$H$2:$H$178,A7) | D7: =COUNTIFS(一覧!$G$2:$G$178,A7,一覧!$D$2:$D$178,"プライム")
A8: 買取再販 | B8: =COUNTIF(一覧!$G$2:$G$178,A8) | C8: =COUNTIF(一覧!$G$2:$G$178,A8)+COUNTIF(一覧!$H$2:$H$178,A8) | D8: =COUNTIFS(一覧!$G$2:$G$178,A8,一覧!$D$2:$D$178,"プライム")
A9: ビル・商業 | B9: =COUNTIF(一覧!$G$2:$G$178,A9) | C9: =COUNTIF(一覧!$G$2:$G$178,A9)+COUNTIF(一覧!$H$2:$H$178,A9) | D9: =COUNTIFS(一覧!$G$2:$G$178,A9,一覧!$D$2:$D$178,"プライム")
A10: 仲介 | B10: =COUNTIF(一覧!$G$2:$G$178,A10) | C10: =COUNTIF(一覧!$G$2:$G$178,A10)+COUNTIF(一覧!$H$2:$H$178,A10) | D10: =COUNTIFS(一覧!$G$2:$G$178,A10,一覧!$D$2:$D$178,"プライム")
A11: ファンド・再生 | B11: =COUNTIF(一覧!$G$2:$G$178,A11) | C11: =COUNTIF(一覧!$G$2:$G$178,A11)+COUNTIF(一覧!$H$2:$H$178,A11) | D11: =COUNTIFS(一覧!$G$2:$G$178,A11,一覧!$D$2:$D$178,"プライム")
A12: テック | B12: =COUNTIF(一覧!$G$2:$G$178,A12) | C12: =COUNTIF(一覧!$G$2:$G$178,A12)+COUNTIF(一覧!$H$2:$H$178,A12) | D12: =COUNTIFS(一覧!$G$2:$G$178,A12,一覧!$D$2:$D$178,"プライム")
A13: 駐車場・スペース | B13: =COUNTIF(一覧!$G$2:$G$178,A13) | C13: =COUNTIF(一覧!$G$2:$G$178,A13)+COUNTIF(一覧!$H$2:$H$178,A13) | D13: =COUNTIFS(一覧!$G$2:$G$178,A13,一覧!$D$2:$D$178,"プライム")
A14: その他 | B14: =COUNTIF(一覧!$G$2:$G$178,A14) | C14: =COUNTIF(一覧!$G$2:$G$178,A14)+COUNTIF(一覧!$H$2:$H$178,A14) | D14: =COUNTIFS(一覧!$G$2:$G$178,A14,一覧!$D$2:$D$178,"プライム")
A15: 合計 | B15: =SUM(B2:B14) | D15: =SUM(D2:D14)
A17: 区分別
A18: 不動産業 | B18: =COUNTIF(一覧!$F$2:$F$178,A18)
A19: 住宅関連（他業種） | B19: =COUNTIF(一覧!$F$2:$F$178,A19)

Sheet 注記
A1: 注記
A2: 出典：日本取引所グループ（JPX）「東証上場銘柄一覧」2026年8月末時点（data_j.xls）をGitHub上の公開ミラーから取得（JPXサイトはこの作業環境から直接接続できなかったため）。
A3: 収録範囲①：東証33業種で「不動産業」に分類される全161社（プライム・スタンダード・グロース・TOKYO PRO Market）。
A4: 収録範囲②：業種は「建設業」「化学」「サービス業」「情報・通信業」だが住宅・不動産が主力／大きな柱の16社（大東建託以外のアパート・注文住宅系、長谷工など）。
A5: 「主分類」「副分類」「主な事業」はClaudeの知識による分類で、各社IRでの裏取りはしていない。2026年10月、当初「要確認」だった34社（主にTOKYO PRO Market）を検索で調査し、分類・事業内容を更新した（緑色の行。K列に根拠URL）。検索結果の抜粋に基づく判断で、各社の開示書類の精読まではしていない。
A6: 非上場の会社（例：一条工務店、ミサワホーム、東急リバブル単体など上場親会社の子会社）とJ-REITは含まない。
A7: 「分類別の社数」シートは一覧シートを数える式で作っているので、分類を書き換えると自動で集計が変わる。
A8: 2026年8月末以降の新規上場・上場廃止は反映されていない。
A9: 調査メモ：5531エヌバイテクノロジーズは2026年6月に中山不動産から社名変更。8938グローム・ホールディングスは医療関連が主力で不動産は縮小中。561Aマークスライフ・617Aレイシャスは本社所在地を確認できず。
